Workbook

Sheet Descriptions
A1: Room ID | B1: Picture ID | C1: Description | D1: N | E1: S | F1: E | G1: W | H1: U | I1: D | J1: Objects
A2: 1 | B2: =DEC2HEX(A2,2) -> 01 | C2: I'm in an Ultramodern City | J2: Strange Lake | K2: Sign | L2: Small Speaker | M2: Huge Door | N2: Long Bridge
A3: 2 | B3: =DEC2HEX(A3,2) -> 02 | C3: I'm in a Long Metal Tunnel | F3: 4 | G3: 3
A4: 3 | B4: =DEC2HEX(A4,2) -> 03 | C4: I'm in a Long Metal Tunnel | F4: 2 | G4: 4
A5: 4 | B5: =DEC2HEX(A5,2) -> 04 | C5: I'm in a Long Metal Tunnel | F5: 3 | G5: 2
A6: 5 | B6: =DEC2HEX(A6,2) -> 05 | C6: I'm on a Metal Paved Street | G6: 6 | J6: Steel Door
A7: 6 | B7: =DEC2HEX(A7,2) -> 06 | C7: I'm on a Metal Paved Street | F7: 5 | G7: 9 | J7: Cylindrical Building | K7: Thin Beam of Light | L7: Steel Door | M7: Robot
A8: 7 | B8: =DEC2HEX(A8,2) -> 07 | C8: I'm in a Laboratory | F8: 8 | J8: Strange Device
A9: 8 | B9: =DEC2HEX(A9,2) -> 08 | C9: I'm in a Laboratory | G9: 7 | J9: Chemicals | K9: Beaker
A10: 9 | B10: =DEC2HEX(A10,2) -> 09 | C10: I'm on a Metal Road | D10: 13 | E10: 10 | F10: 6
A11: 10 | B11: =DEC2HEX(A11,2) -> 0A | C11: I'm on a Metal Road | D11: 9 | J11: Repository | K11: Thin Beam of Light | L11: Steel Door
A12: 11 | B12: =DEC2HEX(A12,2) -> 0B | C12: I'm in a Repository | J12: Small Token | K12: Plastic Rod
A13: 12 | B13: =DEC2HEX(A13,2) -> 0C | C13: I'm on an Escalator
A14: 13 | B14: =DEC2HEX(A14,2) -> 0D | C14: I'm at the Transportation Center | E14: 9 | J14: Crystalline Cube | K14: Monorail
A15: 14 | B15: =DEC2HEX(A15,2) -> 0E | C15: I'm on a Monorail | J15: Control Panel | K15: Open Door
A16: 15 | B16: =DEC2HEX(A16,2) -> 0F | C16: I'm in a Subterranean Shaft | D16: 18 | E16: 1 | J16: Steel Door
A17: 16 | B17: =DEC2HEX(A17,2) -> 10 | C17: I'm in a Small Grotto | G17: 15 | J17: Control Panel
A18: 17 | B18: =DEC2HEX(A18,2) -> 11 | C18: I'm at a Dead End | G18: 18 | J18: Small Tokens
A19: 18 | B19: =DEC2HEX(A19,2) -> 12 | C19: I'm in a Subterranean Shaft | E19: 15 | F19: 17
A20: 19 | B20: =DEC2HEX(A20,2) -> 13 | C20: I'm in a Control Center | D20: 24 | E20: 20 | J20: Control Panel
A21: 20 | B21: =DEC2HEX(A21,2) -> 14 | C21: I'm in an Underground Building | D21: 19 | J21: Lead Room
A22: 21 | B22: =DEC2HEX(A22,2) -> 15 | C22: I'm in a Small Lead Room
A23: 22 | B23: =DEC2HEX(A23,2) -> 16 | C23: I'm on a Metal Platform | D23: 23 | J23: Control Panel
A24: 23 | B24: =DEC2HEX(A24,2) -> 17 | C24: I'm in a Small Metal Room | F24: 24 | J24: Metal Platform
A25: 24 | B25: =DEC2HEX(A25,2) -> 18 | C25: I'm in a Hallway | D25: 26 | E25: 19 | G25: 23 | J25: Thin Beam of Light | K25: Steel Door
A26: 25 | B26: =DEC2HEX(A26,2) -> 19 | C26: I'm in a Storeroom | J26: Robot
A27: 26 | B27: =DEC2HEX(A27,2) -> 1A | C27: I'm in a Steel Chamber | E27: 24 | J27: Screwdriver
A28: 27 | B28: =DEC2HEX(A28,2) -> 1B | C28: I'm on a Metal Platform | F28: 29 | J28: Control Panel
A29: 28 | B29: =DEC2HEX(A29,2) -> 1C | C29: I'm in a Long Corridor | D29: 31 | E29: 41 | F29: 31 | G29: 28 | H29: 31 | I29: 28
A30: 29 | B30: =DEC2HEX(A30,2) -> 1D | C30: I'm in a Small Room | E30: 31 | F30: 30 | J30: Metal Platform
A31: 30 | B31: =DEC2HEX(A31,2) -> 1E | C31: I'm in a Robot Assembly Room | G31: 29 | J31: Compartment | K31: Robot Parts | L31: Small Cartridge
A32: 31 | B32: =DEC2HEX(A32,2) -> 1F | C32: I'm in a Long Corridor | D32: 29 | E32: 36 | F32: 31 | G32: 28 | H32: 28 | I32: 31
A33: 32 | B33: =DEC2HEX(A33,2) -> 20 | C33: I'm in a Deserted Reactor | F33: 33 | J33: Red Key | K33: Atomic Waste
A34: 33 | B34: =DEC2HEX(A34,2) -> 21 | C34: I'm in a Decaying Field | E34: 38 | J34: Reactor
A35: 34 | B35: =DEC2HEX(A35,2) -> 22 | C35: <no description>
A36: 35 | B36: =DEC2HEX(A36,2) -> 23 | C36: I'm in a Small White Room | E36: 39 | J36: Red Button
A37: 36 | B37: =DEC2HEX(A37,2) -> 24 | C37: I'm in a Long Corridor | D37: 31 | J37: Thin Beam of Light
A38: 37 | B38: =DEC2HEX(A38,2) -> 25 | C38: I'm at a Security Control Station | E38: 40 | J38: Lever | K38: Keyhole
A39: 38 | B39: =DEC2HEX(A39,2) -> 26 | C39: I'm on a Forlorn Road | E39: 39 | J39: Small Box
A40: 39 | B40: =DEC2HEX(A40,2) -> 27 | C40: I'm on a Forlorn Road | E40: 42 | G40: 38 | J40: Small Building
...

Sheet Texts
A1: ID | C1: Text
A2: 1 | B2: =DEC2HEX(A2,2) -> 01 | C2: \WELCOME to "FUTURIA"|a Macintosh Adventure|by William Demas||Dedicated to All Mac|Owners Everywhere...|
A3: 2 | B3: =DEC2HEX(A3,2) -> 02 | C3: \It Says:|Watch for The Next Adventure|"UTOPIA" Coming Soon!||
A4: 3 | B4: =DEC2HEX(A4,2) -> 03 | C4: \The Door Slides Open!
A5: 4 | B5: =DEC2HEX(A5,2) -> 04 | C5: \My Hand Breaks the Beam and
A6: 5 | B6: =DEC2HEX(A6,2) -> 05 | C6: \How?
A7: 6 | B7: =DEC2HEX(A7,2) -> 06 | C7: \The Door is Wired!|I'm ELECTROCUTED!!||
A8: 7 | B8: =DEC2HEX(A8,2) -> 07 | C8: \Sorry
A9: 8 | B9: =DEC2HEX(A9,2) -> 08 | C9: \I Can't.
A10: 9 | B10: =DEC2HEX(A10,2) -> 09 | C10: \Laying in a Pool of Oil.
A11: 10 | B11: =DEC2HEX(A11,2) -> 0A | C11: \ZAP!
A12: 11 | B12: =DEC2HEX(A12,2) -> 0B | C12: \Robot
A13: 12 | B13: =DEC2HEX(A13,2) -> 0C | C13: \Won't Let Me.
... A50: 49 | B50: =DEC2HEX(A50,2) -> 31 | C50: \Lever
A51: 50 | B51: =DEC2HEX(A51,2) -> 32 | C51: \and | D51: 1 | E51: A | F51: COSMIC
A52: 51 | B52: =DEC2HEX(A52,2) -> 33 | C52: \Slot | D52: 2 | E52: B
A53: 52 | B53: =DEC2HEX(A53,2) -> 34 | C53: \|An Alluring Voice Says: | D53: 3 | E53: C
A54: 53 | B54: =DEC2HEX(A54,2) -> 35 | C54: \"PASSWORD PLEASE!" | D54: 4 | E54: D
A55: 54 | B55: =DEC2HEX(A55,2) -> 36 | C55: \"INSERT COIN PLEASE!" | D55: 5 | E55: E
A56: 55 | B56: =DEC2HEX(A56,2) -> 37 | C56: \It's Rusty. | D56: 6 | E56: F
A57: 56 | B57: =DEC2HEX(A57,2) -> 38 | C57: \We're Moving! | D57: 7 | E57: G
A58: 57 | B58: =DEC2HEX(A58,2) -> 39 | C58: \We're Heading Underground!|It's Getting Dark!| | D58: 8 | E58: H
A59: 58 | B59: =DEC2HEX(A59,2) -> 3A | C59: \We're Above Ground Again. | D59: 9 | E59: I
A60: 59 | B60: =DEC2HEX(A60,2) -> 3B | C60: \We've Stopped. | D60: 10 | E60: J
A61: 60 | B61: =DEC2HEX(A61,2) -> 3C | C61: \It Says:|Welcome to FUTURIA|The Password is: 3 15 19 13 9 3.|G O O D L U C K !!|| | D61: 11 | E61: K
A62: 61 | B62: =DEC2HEX(A62,2) -> 3D | C62: \-CLICK- | D62: 12 | E62: L
A63: 62 | B63: =DEC2HEX(A63,2) -> 3E | C63: \Vaporizes. | D63: 13 | E63: M
... A76: 75 | B76: =DEC2HEX(A76,2) -> 4B | C76: \Sick | D76: 26 | E76: Z
A77: 76 | B77: =DEC2HEX(A77,2) -> 4C | C77: \I Die of Radiation Poisoning.|
A78: 77 | B78: =DEC2HEX(A78,2) -> 4D | C78: \Something
A79: 78 | B79: =DEC2HEX(A79,2) -> 4E | C79: \I Hear
A80: 79 | B80: =DEC2HEX(A80,2) -> 4F | C80: \Bright Flash of Light!
A81: 80 | B81: =DEC2HEX(A81,2) -> 50 | C81: \There's a
A82: 81 | B82: =DEC2HEX(A82,2) -> 51 | C82: \Yellow
A83: 82 | B83: =DEC2HEX(A83,2) -> 52 | C83: \Spot Me and
A84: 83 | B84: =DEC2HEX(A84,2) -> 53 | C84: \Key
A85: 84 | B85: =DEC2HEX(A85,2) -> 54 | C85: \Card
A86: 85 | B86: =DEC2HEX(A86,2) -> 55 | C86: \in it.
A87: 86 | B87: =DEC2HEX(A87,2) -> 56 | C87: \Seems to be
A88: 87 | B88: =DEC2HEX(A88,2) -> 57 | C88: \I Also See an Empty Slot.
...

Sheet Vocabulary
A1: ID | C1: VERBS | D1: NOUNS
A2: 1 | B2: =DEC2HEX(A2,2) -> 01 | C2: GET/TAKE/GRAB/HOLD/CARR/FETC* | D2: ANY*
A3: 2 | B3: =DEC2HEX(A3,2) -> 02 | C3: DROP/PUT* | D3: NORT*
A4: 3 | B4: =DEC2HEX(A4,2) -> 03 | C4: GO/WALK/RIDE/STEP/ENTE/EXIT/RUN/CROS/SWIM/JUMP* | D4: SOUT*
A5: 4 | B5: =DEC2HEX(A5,2) -> 04 | C5: TOUC/FEEL* | D5: EAST*
A6: 5 | B6: =DEC2HEX(A6,2) -> 05 | C6: KILL/DEST/WREC/RUIN/SMAS/BREA/ATTA* | D6: WEST*
A7: 6 | B7: =DEC2HEX(A7,2) -> 06 | C7: EXAM/LOOK/INSP/SEAR/VIEW/SEE/READ* | D7: UP*
A8: 7 | B8: =DEC2HEX(A8,2) -> 07 | C8: MIX/BLEN/STIR* | D8: DOWN*
A9: 8 | B9: =DEC2HEX(A9,2) -> 08 | C9: FILL* | D9: DOOR*
A10: 9 | B10: =DEC2HEX(A10,2) -> 09 | C10: USE/WITH* | D10: INVE*
A11: 10 | B11: =DEC2HEX(A11,2) -> 0A | C11: BEND/FLEX/TWIS* | D11: OPEN/HOLE*
A12: 11 | B12: =DEC2HEX(A12,2) -> 0B | C12: PUSH/PRES/SHOV* | D12: BUIL*
A13: 12 | B13: =DEC2HEX(A13,2) -> 0C | C13: PULL* | D13: LIGH/BEAM*
... A43: 42 | B43: =DEC2HEX(A43,2) -> 2A | C43: MAGIC | D43: PLAT*
A44: 43 | B44: =DEC2HEX(A44,2) -> 2B | D44: SCRE*
A45: 44 | B45: =DEC2HEX(A45,2) -> 2C | D45: VENT*
A46: 45 | B46: =DEC2HEX(A46,2) -> 2D | D46: CART*
A47: 46 | B47: =DEC2HEX(A47,2) -> 2E | D47: FORC/FIEL*
A48: 47 | B48: =DEC2HEX(A48,2) -> 2F | D48: WIND*
A49: 48 | B49: =DEC2HEX(A49,2) -> 30 | D49: PANE/CONT*
A50: 49 | B50: =DEC2HEX(A50,2) -> 31 | D50: SIGN*
A51: 50 | B51: =DEC2HEX(A51,2) -> 32 | D51: LAKE/WATE*
A52: 51 | B52: =DEC2HEX(A52,2) -> 33 | D52: SPEA*
A53: 52 | B53: =DEC2HEX(A53,2) -> 34 | D53: GAME*
A54: 53 | B54: =DEC2HEX(A54,2) -> 35 | D54: PART*
A55: 54 | B55: =DEC2HEX(A55,2) -> 36 | D55: COSMIC*
... A64: 63 | B64: =DEC2HEX(A64,2) -> 3F | D64: ESCA

Sheet Messages
A1: ID | C1: Messages
A2: 1 | B2: =DEC2HEX(A2,2) -> 01 | C2: I Can't See Anything. It's Too DARK!
A3: 2 | B3: =DEC2HEX(A3,2) -> 02 | C3: Exits:
A4: 3 | B4: =DEC2HEX(A4,2) -> 03 | C4: I See No Obvious Exits.
A5: 4 | B5: =DEC2HEX(A5,2) -> 04 | C5: (I Don't See Anything)
A6: 5 | B6: =DEC2HEX(A6,2) -> 05 | C6: Things That I See:
A7: 6 | B7: =DEC2HEX(A7,2) -> 06 | C7: I Don't Know the (Huh?)|Noun|"Verb|"
A8: 7 | B8: =DEC2HEX(A8,2) -> 07 | C8: |I'm Carrying:|
A9: 8 | B9: =DEC2HEX(A9,2) -> 08 | C9: |I'm Dead!|
A10: 9 | B10: =DEC2HEX(A10,2) -> 09 | C10: |I Beg Your Pardon ?
A11: 10 | B11: =DEC2HEX(A11,2) -> 0A | C11: I Don't See it Here...
A12: 11 | B12: =DEC2HEX(A12,2) -> 0B | C12: I Already Have it!|"TAKE INVENTORY"
A13: 12 | B13: =DEC2HEX(A13,2) -> 0C | C13: I'm Carrying Too Much!|Drop Something First!!!
... A42: 41 | B42: =DEC2HEX(A42,2) -> 29 | C42: Saved Game

Sheet Objects
A1: ID | C1: Room ID | D1: Objects
A2: 1 | B2: =DEC2HEX(A2,2) -> 01 | C2: $01 | D2: \.Strange Lake | E2: =IF(C2="$00","Not created","")
A3: 2 | B3: =DEC2HEX(A3,2) -> 02 | C3: $01 | D3: \Sign | E3: =IF(C3="$00","Not created","")
A4: 3 | B4: =DEC2HEX(A4,2) -> 03 | C4: $01 | D4: \Small Speaker | E4: =IF(C4="$00","Not created","")
A5: 4 | B5: =DEC2HEX(A5,2) -> 04 | C5: $01 | D5: \Huge Door | E5: =IF(C5="$00","Not created","")
A6: 5 | B6: =DEC2HEX(A6,2) -> 05 | C6: $00 | D6: \Opening | E6: =IF(C6="$00","Not created","") -> Not created
A7: 6 | B7: =DEC2HEX(A7,2) -> 06 | C7: $06 | D7: \Cylindrical Building | E7: =IF(C7="$00","Not created","")
A8: 7 | B8: =DEC2HEX(A8,2) -> 07 | C8: $06 | D8: \Thin Beam of Light | E8: =IF(C8="$00","Not created","")
A9: 8 | B9: =DEC2HEX(A9,2) -> 08 | C9: $06 | D9: \Steel Door | E9: =IF(C9="$00","Not created","")
A10: 9 | B10: =DEC2HEX(A10,2) -> 09 | C10: $07 | D10: \Strange Device | E10: =IF(C10="$00","Not created","")
A11: 10 | B11: =DEC2HEX(A11,2) -> 0A | C11: $08 | D11: \Chemicals | E11: =IF(C11="$00","Not created","")
A12: 11 | B12: =DEC2HEX(A12,2) -> 0B | C12: $0D | D12: \Crystalline Cube | E12: =IF(C12="$00","Not created","")
A13: 12 | B13: =DEC2HEX(A13,2) -> 0C | C13: $0A | D13: \Repository | E13: =IF(C13="$00","Not created","")
... A104: 103 | B104: =DEC2HEX(A104,2) -> 67 | C104: $42 | D104: \Long Bridge | E104: =IF(C104="$00","Not created","")
E105: =IF(C105="$00","Not created","")

Sheet Game
B1: Verb index | C1: Noun index | D1: Verb | E1: Noun
A2: 010F0909A010 | B2: =LEFT(A2,2) -> 01 | C2: =MID(A2,3,2) -> 0F | D2: =VLOOKUP(B2,Vocabulary!B:D,2,TRUE) -> GET/TAKE/GRAB/HOLD/CARR/FETC* | E2: =VLOOKUP(C2,Vocabulary!B:D,3,TRUE) -> DEVI*
A3: 0110090AA010 | B3: =LEFT(A3,2) -> 01 | C3: =MID(A3,3,2) -> 10 | D3: =VLOOKUP(B3,Vocabulary!B:D,2,TRUE) -> GET/TAKE/GRAB/HOLD/CARR/FETC* | E3: =VLOOKUP(C3,Vocabulary!B:D,3,TRUE) -> CHEM*
A4: 0114090DA010 | B4: =LEFT(A4,2) -> 01 | C4: =MID(A4,3,2) -> 14 | D4: =VLOOKUP(B4,Vocabulary!B:D,2,TRUE) -> GET/TAKE/GRAB/HOLD/CARR/FETC* | E4: =VLOOKUP(C4,Vocabulary!B:D,3,TRUE) -> TOKE/COIN*
A5: 0113090EA010 | B5: =LEFT(A5,2) -> 01 | C5: =MID(A5,3,2) -> 13 | D5: =VLOOKUP(B5,Vocabulary!B:D,2,TRUE) -> GET/TAKE/GRAB/HOLD/CARR/FETC* | E5: =VLOOKUP(C5,Vocabulary!B:D,3,TRUE) -> ROD/PLAS*
A6: 01130912A010 | B6: =LEFT(A6,2) -> 01 | C6: =MID(A6,3,2) -> 13 | D6: =VLOOKUP(B6,Vocabulary!B:D,2,TRUE) -> GET/TAKE/GRAB/HOLD/CARR/FETC* | E6: =VLOOKUP(C6,Vocabulary!B:D,3,TRUE) -> ROD/PLAS*
A7: 011D0918A010 | B7: =LEFT(A7,2) -> 01 | C7: =MID(A7,3,2) -> 1D | D7: =VLOOKUP(B7,Vocabulary!B:D,2,TRUE) -> GET/TAKE/GRAB/HOLD/CARR/FETC* | E7: =VLOOKUP(C7,Vocabulary!B:D,3,TRUE) -> CANI*
A8: 0127091CA010 | B8: =LEFT(A8,2) -> 01 | C8: =MID(A8,3,2) -> 27 | D8: =VLOOKUP(B8,Vocabulary!B:D,2,TRUE) -> GET/TAKE/GRAB/HOLD/CARR/FETC* | E8: =VLOOKUP(C8,Vocabulary!B:D,3,TRUE) -> GREE*
A9: 0121091DA010 | B9: =LEFT(A9,2) -> 01 | C9: =MID(A9,3,2) -> 21 | D9: =VLOOKUP(B9,Vocabulary!B:D,2,TRUE) -> GET/TAKE/GRAB/HOLD/CARR/FETC* | E9: =VLOOKUP(C9,Vocabulary!B:D,3,TRUE) -> LASE/PIST*
A10: 0122091EA0101EB0 | B10: =LEFT(A10,2) -> 01 | C10: =MID(A10,3,2) -> 22 | D10: =VLOOKUP(B10,Vocabulary!B:D,2,TRUE) -> GET/TAKE/GRAB/HOLD/CARR/FETC* | E10: =VLOOKUP(C10,Vocabulary!B:D,3,TRUE) -> BOX*
A11: 01280922A010 | B11: =LEFT(A11,2) -> 01 | C11: =MID(A11,3,2) -> 28 | D11: =VLOOKUP(B11,Vocabulary!B:D,2,TRUE) -> GET/TAKE/GRAB/HOLD/CARR/FETC* | E11: =VLOOKUP(C11,Vocabulary!B:D,3,TRUE) -> RED*
A12: 01140926A010 | B12: =LEFT(A12,2) -> 01 | C12: =MID(A12,3,2) -> 14 | D12: =VLOOKUP(B12,Vocabulary!B:D,2,TRUE) -> GET/TAKE/GRAB/HOLD/CARR/FETC* | E12: =VLOOKUP(C12,Vocabulary!B:D,3,TRUE) -> TOKE/COIN*
A13: 012B0929A01029B0 | B13: =LEFT(A13,2) -> 01 | C13: =MID(A13,3,2) -> 2B | D13: =VLOOKUP(B13,Vocabulary!B:D,2,TRUE) -> GET/TAKE/GRAB/HOLD/CARR/FETC* | E13: =VLOOKUP(C13,Vocabulary!B:D,3,TRUE) -> SCRE*
... A46: 06320701A00F | B46: =LEFT(A46,2) -> 06 | C46: =MID(A46,3,2) -> 32 | D46: =VLOOKUP(B46,Vocabulary!B:D,2,TRUE) -> EXAM/LOOK/INSP/SEAR/VIEW/SEE/READ* | E46: =VLOOKUP(C46,Vocabulary!B:D,3,TRUE) -> LAKE/WATE*
A47: 30807010916 | B47: =LEFT(A47,2) -> 30 | C47: =MID(A47,3,2) -> 80 | D47: =VLOOKUP(B47,Vocabulary!B:D,2,TRUE) -> 0 | E47: =VLOOKUP(C47,Vocabulary!B:D,3,TRUE) -> ESCA
A48: 30807020916 | B48: =LEFT(A48,2) -> 30 | C48: =MID(A48,3,2) -> 80 | D48: =VLOOKUP(B48,Vocabulary!B:D,2,TRUE) -> 0 | E48: =VLOOKUP(C48,Vocabulary!B:D,3,TRUE) -> ESCA
A49: 06310902A00F02B0 | B49: =LEFT(A49,2) -> 06 | C49: =MID(A49,3,2) -> 31 | D49: =VLOOKUP(B49,Vocabulary!B:D,2,TRUE) -> EXAM/LOOK/INSP/SEAR/VIEW/SEE/READ* | E49: =VLOOKUP(C49,Vocabulary!B:D,3,TRUE) -> SIGN*
A50: 030A09050704 | B50: =LEFT(A50,2) -> 03 | C50: =MID(A50,3,2) -> 0A | D50: =VLOOKUP(B50,Vocabulary!B:D,2,TRUE) -> GO/WALK/RIDE/STEP/ENTE/EXIT/RUN/CROS/SWIM/JUMP* | E50: =VLOOKUP(C50,Vocabulary!B:D,3,TRUE) -> OPEN/HOLE*
A51: 060E07060923 | B51: =LEFT(A51,2) -> 06 | C51: =MID(A51,3,2) -> 0E | D51: =VLOOKUP(B51,Vocabulary!B:D,2,TRUE) -> EXAM/LOOK/INSP/SEAR/VIEW/SEE/READ* | E51: =VLOOKUP(C51,Vocabulary!B:D,3,TRUE) -> ROBO*
A52: 040C07060A16 | B52: =LEFT(A52,2) -> 04 | C52: =MID(A52,3,2) -> 0C | D52: =VLOOKUP(B52,Vocabulary!B:D,2,TRUE) -> TOUC/FEEL* | E52: =VLOOKUP(C52,Vocabulary!B:D,3,TRUE) -> LIGH/BEAM*
A53: 30807060916 | B53: =LEFT(A53,2) -> 30 | C53: =MID(A53,3,2) -> 80 | D53: =VLOOKUP(B53,Vocabulary!B:D,2,TRUE) -> 0 | E53: =VLOOKUP(C53,Vocabulary!B:D,3,TRUE) -> ESCA
A54: 30807060916 | B54: =LEFT(A54,2) -> 30 | C54: =MID(A54,3,2) -> 80 | D54: =VLOOKUP(B54,Vocabulary!B:D,2,TRUE) -> 0 | E54: =VLOOKUP(C54,Vocabulary!B:D,3,TRUE) -> ESCA
A55: 30807060908 | B55: =LEFT(A55,2) -> 30 | C55: =MID(A55,3,2) -> 80 | D55: =VLOOKUP(B55,Vocabulary!B:D,2,TRUE) -> 0 | E55: =VLOOKUP(C55,Vocabulary!B:D,3,TRUE) -> ESCA
A56: 030B0706A00F | B56: =LEFT(A56,2) -> 03 | C56: =MID(A56,3,2) -> 0B | D56: =VLOOKUP(B56,Vocabulary!B:D,2,TRUE) -> GO/WALK/RIDE/STEP/ENTE/EXIT/RUN/CROS/SWIM/JUMP* | E56: =VLOOKUP(C56,Vocabulary!B:D,3,TRUE) -> BUIL*
A57: 060C0907A00F | B57: =LEFT(A57,2) -> 06 | C57: =MID(A57,3,2) -> 0C | D57: =VLOOKUP(B57,Vocabulary!B:D,2,TRUE) -> EXAM/LOOK/INSP/SEAR/VIEW/SEE/READ* | E57: =VLOOKUP(C57,Vocabulary!B:D,3,TRUE) -> LIGH/BEAM*
A58: 010E09230706 | B58: =LEFT(A58,2) -> 01 | C58: =MID(A58,3,2) -> 0E | D58: =VLOOKUP(B58,Vocabulary!B:D,2,TRUE) -> GET/TAKE/GRAB/HOLD/CARR/FETC* | E58: =VLOOKUP(C58,Vocabulary!B:D,3,TRUE) -> ROBO*
A59: 050E09230706 | B59: =LEFT(A59,2) -> 05 | C59: =MID(A59,3,2) -> 0E | D59: =VLOOKUP(B59,Vocabulary!B:D,2,TRUE) -> KILL/DEST/WREC/RUIN/SMAS/BREA/ATTA* | E59: =VLOOKUP(C59,Vocabulary!B:D,3,TRUE) -> ROBO*
A60: 03080705A00F | B60: =LEFT(A60,2) -> 03 | C60: =MID(A60,3,2) -> 08 | D60: =VLOOKUP(B60,Vocabulary!B:D,2,TRUE) -> GO/WALK/RIDE/STEP/ENTE/EXIT/RUN/CROS/SWIM/JUMP* | E60: =VLOOKUP(C60,Vocabulary!B:D,3,TRUE) -> DOOR*
A61: 30807070908 | B61: =LEFT(A61,2) -> 30 | C61: =MID(A61,3,2) -> 80 | D61: =VLOOKUP(B61,Vocabulary!B:D,2,TRUE) -> 0 | E61: =VLOOKUP(C61,Vocabulary!B:D,3,TRUE) -> ESCA
A62: 30807070916 | B62: =LEFT(A62,2) -> 30 | C62: =MID(A62,3,2) -> 80 | D62: =VLOOKUP(B62,Vocabulary!B:D,2,TRUE) -> 0 | E62: =VLOOKUP(C62,Vocabulary!B:D,3,TRUE) -> ESCA
A63: 040C07070A16 | B63: =LEFT(A63,2) -> 04 | C63: =MID(A63,3,2) -> 0C | D63: =VLOOKUP(B63,Vocabulary!B:D,2,TRUE) -> TOUC/FEEL* | E63: =VLOOKUP(C63,Vocabulary!B:D,3,TRUE) -> LIGH/BEAM*
A64: 07100B0AA00F | B64: =LEFT(A64,2) -> 07 | C64: =MID(A64,3,2) -> 10 | D64: =VLOOKUP(B64,Vocabulary!B:D,2,TRUE) -> MIX/BLEN/STIR* | E64: =VLOOKUP(C64,Vocabulary!B:D,3,TRUE) -> CHEM*
A65: 13080705A00F | B65: =LEFT(A65,2) -> 13 | C65: =MID(A65,3,2) -> 08 | D65: =VLOOKUP(B65,Vocabulary!B:D,2,TRUE) -> OPEN/UNLO/UNCO* | E65: =VLOOKUP(C65,Vocabulary!B:D,3,TRUE) -> DOOR*
A66: 13080908A00F | B66: =LEFT(A66,2) -> 13 | C66: =MID(A66,3,2) -> 08 | D66: =VLOOKUP(B66,Vocabulary!B:D,2,TRUE) -> OPEN/UNLO/UNCO* | E66: =VLOOKUP(C66,Vocabulary!B:D,3,TRUE) -> DOOR*
A67: 13080948A00F | B67: =LEFT(A67,2) -> 13 | C67: =MID(A67,3,2) -> 08 | D67: =VLOOKUP(B67,Vocabulary!B:D,2,TRUE) -> OPEN/UNLO/UNCO* | E67: =VLOOKUP(C67,Vocabulary!B:D,3,TRUE) -> DOOR*
A68: 060C0947A00F | B68: =LEFT(A68,2) -> 06 | C68: =MID(A68,3,2) -> 0C | D68: =VLOOKUP(B68,Vocabulary!B:D,2,TRUE) -> EXAM/LOOK/INSP/SEAR/VIEW/SEE/READ* | E68: =VLOOKUP(C68,Vocabulary!B:D,3,TRUE) -> LIGH/BEAM*
A69: 040C070A0A49 | B69: =LEFT(A69,2) -> 04 | C69: =MID(A69,3,2) -> 0C | D69: =VLOOKUP(B69,Vocabulary!B:D,2,TRUE) -> TOUC/FEEL* | E69: =VLOOKUP(C69,Vocabulary!B:D,3,TRUE) -> LIGH/BEAM*
A70: 040C070B0A49 | B70: =LEFT(A70,2) -> 04 | C70: =MID(A70,3,2) -> 0C | D70: =VLOOKUP(B70,Vocabulary!B:D,2,TRUE) -> TOUC/FEEL* | E70: =VLOOKUP(C70,Vocabulary!B:D,3,TRUE) -> LIGH/BEAM*
A71: 03080948A00F | B71: =LEFT(A71,2) -> 03 | C71: =MID(A71,3,2) -> 08 | D71: =VLOOKUP(B71,Vocabulary!B:D,2,TRUE) -> GO/WALK/RIDE/STEP/ENTE/EXIT/RUN/CROS/SWIM/JUMP* | E71: =VLOOKUP(C71,Vocabulary!B:D,3,TRUE) -> DOOR*
A72: 0308070A0949 | B72: =LEFT(A72,2) -> 03 | C72: =MID(A72,3,2) -> 08 | D72: =VLOOKUP(B72,Vocabulary!B:D,2,TRUE) -> GO/WALK/RIDE/STEP/ENTE/EXIT/RUN/CROS/SWIM/JUMP* | E72: =VLOOKUP(C72,Vocabulary!B:D,3,TRUE) -> DOOR*
...
