Workbook
Name FILE128: '128K'!$A$1:$B$1044
Name FILE256: '256K'!$A$1:$B$2068
Name FILE64: '64K'!$A$1:$B$791

Sheet 64K
A1: Read file in one pass | B1: File size is 64Kb | D1: 1023000 | E1: 2 | F1: 4
A2: Open entry | B2: 00000000 | C2: =HEX2DEC(B2) -> 0 | D2: =C2/$D$1 -> 0
A3: Open exit | B3: 000186B0
A4: Read entry | B4: 0001876E
A5: Read exit | B5: 00121879
A6: Close entry | B6: 00121945
A7: Close exit | B7: 0012248D | C7: =HEX2DEC(B7) -> 1189005 | D7: =C7/$D$1 -> 1.1622727 | E7: ='128K'!D7/$E$1 -> 1.0996413 | F7: ='256K'!D7/$F$1 -> 1.0902832
A8: Read file per 512 bytes | B8: File size is 64Kb
A9: Open entry | B9: 00000000 | C9: =HEX2DEC(B9) -> 0 | D9: =C9/$D$1 -> 0
A10: Open exit | B10: 000180DB
A11: Read entry | B11: 00018199
A12: Read exit | B12: 00019227
A13: Read entry | B13: 000192E2
A14: Read exit | B14: 0001CAAD
A15: Read entry | B15: 0001CDE3
A16: Read exit | B16: 00020676
A17: Read entry | B17: 00020731
A18: Read exit | B18: 00023FDD
A19: Read entry | B19: 00024098
A20: Read exit | B20: 0002796B
A21: Read entry | B21: 00027A26
... A268: Close entry | B268: 001E53E1
A269: Close exit | B269: 001E5FBD | C269: =HEX2DEC(B269) -> 1990589 | D269: =C269/$D$1 -> 1.9458348 | E269: ='128K'!D525/$E$1 -> 1.9193187 | F269: ='256K'!D1037/$F$1 -> 1.8963903
A270: Read file block-by-block | B270: File size is 64Kb
A271: Open entry | B271: 00000000 | C271: =HEX2DEC(B271) -> 0 | D271: =C271/$D$1 -> 0
A272: Open exit | B272: 002D1FBF
A273: Block read entry | B273: 002D20CC
A274: Block read exit | B274: 002D42C3
A275: Block read entry | B275: 002D43D8
A276: Block read exit | B276: 002D66C5
A277: Block read entry | B277: 002D67DA
A278: Block read exit | B278: 002D89C6
A279: Block read entry | B279: 002D8ADB
A280: Block read exit | B280: 002DAFFB
A281: Block read entry | B281: 002DB110
A282: Block read exit | B282: 002DD41A
A283: Block read entry | B283: 002DD52F
... A529: Close entry | B529: 003EA386
A530: Close exit | B530: 003EA440 | C530: =HEX2DEC(B530) -> 4105280 | D530: =C530/$D$1 -> 4.0129814
A531: Read file b-by-b low level | B531: File size is 64Kb
...

Sheet 128K
A1: Read file in one pass | B1: File size is 128Kb | D1: 1023000
A2: Open entry | B2: 00000000 | C2: =HEX2DEC(B2) -> 0 | D2: =C2/$D$1 -> 0
A3: Open exit | B3: 000190FD
A4: Read entry | B4: 000191BB
A5: Read exit | B5: 00224878
A6: Close entry | B6: 00224944
A7: Close exit | B7: 0022548A | C7: =HEX2DEC(B7) -> 2249866 | D7: =C7/$D$1 -> 2.1992825
A8: Read file per 512 bytes | B8: File size is 128Kb
A9: Open entry | B9: 00000000 | C9: =HEX2DEC(B9) -> 0 | D9: =C9/$D$1 -> 0
A10: Open exit | B10: 00019D4D
A11: Read entry | B11: 00019E0B
A12: Read exit | B12: 0001AE97
A13: Read entry | B13: 0001AF52
A14: Read exit | B14: 0001E809
A15: Read entry | B15: 0001E8C4
A16: Read exit | B16: 00022202
A17: Read entry | B17: 000222BD
A18: Read exit | B18: 00025BFF
A19: Read entry | B19: 00025CBA
A20: Read exit | B20: 000295C6
A21: Read entry | B21: 00029681
... A524: Close entry | B524: 003BDFF8
A525: Close exit | B525: 003BEB8E | C525: =HEX2DEC(B525) -> 3926926 | D525: =C525/$D$1 -> 3.8386373
A526: Read file block-by-block | B526: File size is 128Kb
A527: Open entry | B527: 00000000 | C527: =HEX2DEC(B527) -> 0 | D527: =C527/$D$1 -> 0
A528: Read file b-by-b low level | B528: File size is 128Kb
A529: Open entry | B529: 00000000 | C529: =HEX2DEC(B529) -> 0 | D529: =C529/$D$1 -> 0
A530: Open exit | B530: 00012034
A531: Block read entry | B531: 00012143 | C531: 0 | D531: =C531/$D$1 -> 0
A532: Block read exit | B532: 0001C859 | C532: =HEX2DEC(B532)-HEX2DEC(B531) -> 42774 | D532: =C532/$D$1 -> 0.041812317
A533: Block read entry | B533: 0001C96E | C533: =HEX2DEC(B533)-HEX2DEC(B532) -> 277 | D533: =C533/$D$1 -> 0.00027077224
A534: Block read exit | B534: 0001EB17 | C534: =HEX2DEC(B534)-HEX2DEC(B533) -> 8617 | D534: =C534/$D$1 -> 0.0084232649
A535: Block read entry | B535: 0001EC2C | C535: =HEX2DEC(B535)-HEX2DEC(B534) -> 277 | D535: =C535/$D$1 -> 0.00027077224
A536: Block read exit | B536: 0002104F | C536: =HEX2DEC(B536)-HEX2DEC(B535) -> 9251 | D536: =C536/$D$1 -> 0.0090430108
A537: Block read entry | B537: 00021164 | C537: =HEX2DEC(B537)-HEX2DEC(B536) -> 277 | D537: =C537/$D$1 -> 0.00027077224
A538: Block read exit | B538: 00023592 | C538: =HEX2DEC(B538)-HEX2DEC(B537) -> 9262 | D538: =C538/$D$1 -> 0.0090537634
A539: Block read entry | B539: 000236A7 | C539: =HEX2DEC(B539)-HEX2DEC(B538) -> 277 | D539: =C539/$D$1 -> 0.00027077224
A540: Block read exit | B540: 00025857 | C540: =HEX2DEC(B540)-HEX2DEC(B539) -> 8624 | D540: =C540/$D$1 -> 0.0084301075
A541: Block read entry | B541: 0002596C | C541: =HEX2DEC(B541)-HEX2DEC(B540) -> 277 | D541: =C541/$D$1 -> 0.00027077224
A542: Block read exit | B542: 00027DC1 | C542: =HEX2DEC(B542)-HEX2DEC(B541) -> 9301 | D542: =C542/$D$1 -> 0.0090918866
...

Sheet 256K
A1: Read file in one pass | B1: File size is 256Kb | D1: 1023000
A2: Open entry | B2: 00000000 | C2: =HEX2DEC(B2) -> 0 | D2: =C2/$D$1 -> 0
A3: Open exit | B3: 0001D96F
A4: Read entry | B4: 0001DA2D
A5: Read exit | B5: 004404F3
A6: Close entry | B6: 004405BF
A7: Close exit | B7: 0044137F | C7: =HEX2DEC(B7) -> 4461439 | D7: =C7/$D$1 -> 4.3611329
A8: Read file per 512 bytes | B8: File size is 256Kb
A9: Open entry | B9: 00000000 | C9: =HEX2DEC(B9) -> 0 | D9: =C9/$D$1 -> 0
A10: Open exit | B10: 0001D967
A11: Read entry | B11: 0001DA25
A12: Read exit | B12: 0001EAA7
A13: Read entry | B13: 0001EB62
A14: Read exit | B14: 00022420
A15: Read entry | B15: 000224DB
A16: Read exit | B16: 00025E55
A17: Read entry | B17: 00025F10
A18: Read exit | B18: 00029867
A19: Read entry | B19: 00029922
A20: Read exit | B20: 0002D280
A21: Read entry | B21: 0002D33B
... A1036: Close entry | B1036: 00765CC0
A1037: Close exit | B1037: 0076689D | C1037: =HEX2DEC(B1037) -> 7760029 | D1037: =C1037/$D$1 -> 7.5855611
A1038: Read file block-by-block | B1038: File size is 256Kb
A1039: Open entry | B1039: 00000000 | C1039: =HEX2DEC(B1039) -> 0 | D1039: =C1039/$D$1 -> 0
A1040: Read file b-by-b low level | B1040: File size is 256Kb
A1041: Open entry | B1041: 00000000 | C1041: =HEX2DEC(B1041) -> 0 | D1041: =C1041/$D$1 -> 0
A1042: Open exit | B1042: 00028EA2
A1043: Block read entry | B1043: 00028FB1 | C1043: 0 | D1043: =C1043/$D$1 -> 0
A1044: Block read exit | B1044: 0002B144 | C1044: =HEX2DEC(B1044)-HEX2DEC(B1043) -> 8595 | D1044: =C1044/$D$1 -> 0.0084017595
A1045: Block read entry | B1045: 0002B259 | C1045: =HEX2DEC(B1045)-HEX2DEC(B1044) -> 277 | D1045: =C1045/$D$1 -> 0.00027077224
A1046: Block read exit | B1046: 0002D680 | C1046: =HEX2DEC(B1046)-HEX2DEC(B1045) -> 9255 | D1046: =C1046/$D$1 -> 0.0090469208
A1047: Block read entry | B1047: 0002D795 | C1047: =HEX2DEC(B1047)-HEX2DEC(B1046) -> 277 | D1047: =C1047/$D$1 -> 0.00027077224
A1048: Block read exit | B1048: 0002F933 | C1048: =HEX2DEC(B1048)-HEX2DEC(B1047) -> 8606 | D1048: =C1048/$D$1 -> 0.0084125122
A1049: Block read entry | B1049: 0002FA48 | C1049: =HEX2DEC(B1049)-HEX2DEC(B1048) -> 277 | D1049: =C1049/$D$1 -> 0.00027077224
A1050: Block read exit | B1050: 00031BF8 | C1050: =HEX2DEC(B1050)-HEX2DEC(B1049) -> 8624 | D1050: =C1050/$D$1 -> 0.0084301075
A1051: Block read entry | B1051: 00031D0D | C1051: =HEX2DEC(B1051)-HEX2DEC(B1050) -> 277 | D1051: =C1051/$D$1 -> 0.00027077224
A1052: Block read exit | B1052: 00034187 | C1052: =HEX2DEC(B1052)-HEX2DEC(B1051) -> 9338 | D1052: =C1052/$D$1 -> 0.0091280547
A1053: Block read entry | B1053: 0003429C | C1053: =HEX2DEC(B1053)-HEX2DEC(B1052) -> 277 | D1053: =C1053/$D$1 -> 0.00027077224
A1054: Block read exit | B1054: 00036457 | C1054: =HEX2DEC(B1054)-HEX2DEC(B1053) -> 8635 | D1054: =C1054/$D$1 -> 0.0084408602
...
